Workbook

Sheet Info
A2: We have a modular approach for the data classification
A3: HS= Helpersheet
A4: P=Persona
A5: A=Activity
A6: E=Entity

Sheet Original Dataset
A1: / | C1: Goal - Action | K1: Benefit - Action
A2: User Story Text | B2: Persona | C2: Goal Activity | D2: Goal Entity | E2: Goal Activity 2 | F2: Goal Entity 2 | G2: Goal Activity 3 | H2: Goal Entity 3 | I2: Goal Activity 4 | J2: Goal Entity 4 | K2: Benefit Activity | L2: Benefit Entity | M2: Benefit Activity 2 | N2: Benefit Entity 2 | O2: Benefit Activity 3 | P2: Benefit Entity 3 | Q2: Benefit Activity 4 | R2: Benefit Entity 4 | S2: Benefit Activity 5 | T2: Benefit Entity 5 | U2: Benefit Activity 6 | V2: Benefit Entity 6 | W2: Benefit Activity 7 | X2: Benefit Entity 7
A3: As a Public User, I want to Search for Information, so that I can obtain publicly available information concerning properties, County services, processes and other general information. | B3: Public User | C3: Search | D3: Information | K3: obtain | L3: publicly available information
A4: As a ProspectiveApplicant, I want to research requirements and to select a service, so that I can find the relevant service and/or application type to initiate via the online portal. | B4: ProspectiveApplicant | C4: research | D4: requirements | E4: select | F4: service | K4: find | L4: application type | M4: find | N4: relevant service | O4: initiate | P4: application type | Q4: initiate | R4: relevant service
A5: As an Applicant, I want to Request PreApplication Assistance, so that I can receive a response to a request for a meeting or information that is a result of the preapplication assistance. | B5: Applicant | C5: Request | D5: PreApplication Assistance | K5: receive | L5: response | M5: receive | N5: information
A6: As a Customer, I want to Create a Customer Portal User Account, so that I can log on to the Customer Portal and perform transactions that first require user authentication. | B6: Customer | C6: Create | D6: Customer Portal User Account | K6: log | L6: Customer Portal | M6: perform | N6: transactions
A7: As an Applicant, I want to Submit Application, so that I can provide my information, plans and/or documents to initiate a transaction with the County. | B7: Applicant | C7: Submit | D7: Application | K7: provide | L7: information | M7: provide | N7: plans | O7: provide | P7: documents | Q7: initiate | R7: transaction
A8: As an Applicant, I want to Submit Supporting Documentation, so that I can satisfy documentation requirements for my application. | B8: Applicant | C8: Submit | D8: Supporting Documentation | K8: satisfy | L8: documentation requirements
A9: As an Applicant, I want to Pay Fee, so that I can satisfy outstanding charge associated with the service requested or received from the County. | B9: Applicant | C9: Pay | D9: Fee | K9: satisfy | L9: outstanding charge | M9: received from | N9: County
A10: As an Applicant, I want to Check the Status of a transaction, so that I can understand where the provisioning of my service is in the process, such as information related to service levels, fees, plan review, permit, or inspection results. | B10: Applicant | C10: Check | D10: Status | K10: understand | L10: service
A11: As an Applicant, I want to Modify my Application, so that I can successfully change information on an application. | B11: Applicant | C11: Modify | D11: Application | K11: successfully change | L11: information
A12: As a Staff member, I want to Perform a Completeness Review, so that I can validate when an application is complete and eligible for further technical review. | B12: Staff member | C12: Perform | D12: Completeness Review | K12: validate | L12: eligible for further technical review | M12: validate | N12: application
A13: As a Staff member, I want to Record an Internal Note, so that I can share information with other Staff collaborating on the record. | B13: Staff member | C13: Record | D13: Internal Note | K13: share | L13: information
A14: As a Staff member, I want to Assign an Application for Detailed Review, so that I can review the for compliance and subsequently approved or denied. | B14: Staff member | C14: Assign | D14: Application | K14: review | L14: compliance | M14: subsequently approved | N14: compliance | O14: denied | P14: compliance
A15: As a Staff member, I want to Apply a Hold, so that I can prevent progression through the workflow or other actions in the system until the issue is resolved. | B15: Staff member | C15: Apply | D15: Hold | K15: prevent | L15: progression | M15: prevent | N15: other actions
A16: As a Staff member, I want to Remove a Hold, so that I can allow progression through the workflow or other actions in the system now that the issue has been resolved. | B16: Staff member | C16: Remove | D16: Hold | K16: allow | L16: progression | M16: resolved | N16: issue
A17: As a Staff member, I want to Send a Formal Response to Applicant, so that I can satisfy communication and records responsibilities. | B17: Staff member | C17: Send | D17: Formal Response | K17: satisfy | L17: communication | M17: satisfy | N17: records responsibilities
A18: As a Staff member, I want to Track the Draft Proffers, so that I can preserve the history of draft proffer statements submitted by the Applicant. | B18: Staff member | C18: Track | D18: Draft Proffers | K18: preserve | L18: history of draft proffer statements
A19: As a Staff member, I want to Manage Approved Proffers, so that I can ensure compliance with and satisfaction of the proffer in the future. | B19: Staff member | C19: Manage | D19: Approved Proffers | K19: ensure | L19: compliance | M19: ensure | N19: satisfaction
A20: As a Staff member, I want to Manage Ordinances, so that I can maintain accurate ordinance information in the System. | B20: Staff member | C20: Manage | D20: Ordinances | K20: maintain | L20: accurate ordinance information
A21: As a Staff member, I want to Schedule a Meeting, so that I can bring the required parties together at a specific date/time to address an issue. | B21: Staff member | C21: Schedule | D21: Meeting | K21: bring | L21: required parties | M21: address | N21: issue
A22: As a staff member, I want to denote an application with a Final Action status. So that I can finish it. | B22: staff member | C22: denote | D22: application
A23: As a Planning Staff member, I want to Conduct and Track Plan Amendments and Planning Studies, so that I can record work in process, outcome, and location-based information related to the Plan(s). | B23: Planning Staff member | C23: Track | D23: Plan Amendments | E23: Track | F23: Planning Studies | G23: Conduct | H23: Plan Amendments | I23: Conduct | J23: Planning Studies | K23: record | L23: work in process | M23: record | N23: outcome | O23: record | P23: location-based information
A24: As a Planning Staff member, I want to Generate Planning-related Reports, so that I can access, analyze and/or export the needed information in the format I requested. | B24: Planning Staff member | C24: Generate | D24: Planning-related Reports | K24: access | L24: needed information | M24: analyze | N24: needed information | O24: export | P24: needed information
A25: As a Planning Staff member, I want to Evaluate Consistency with the Comprehensive Plan, so that I can complete my required review of a plan set and/or application. | B25: Planning Staff member | C25: Evaluate | D25: Consistency | K25: complete | L25: required review
A26: As a Staff member, I want to Perform a Staff Review, so that I can validate compliance of an application with the Zoning Ordinance and impact approval/denial of the application accordingly. | B26: Staff member | C26: Perform | D26: Staff Review | K26: validate | L26: compliance
A27: As a Zoning Staff member, I want to Process the Requests for Zoning Information, so that I can capture my response to the request in the system and also send a communication from the system to the Applicant. | B27: Zoning Staff member | C27: Process | D27: Requests | K27: capture | L27: response | M27: send | N27: communication
A28: As a Zoning Staff member, I want to Issue the Zoning-Related Permits, so that I can satisfy an Applicant's request for service that has proven to be eligible and in compliance with the Zoning Ordinance. | B28: Zoning Staff member | C28: Issue | D28: Zoning-Related Permits | K28: satisfy | L28: Applicant's request
A29: As a Staff member, I want to Develop a Staff Report, so that I can publish and distribute the report according to business rules. | B29: Staff member | C29: Develop | D29: Staff Report | K29: publish | L29: report | M29: distribute | N29: report
A30: As a Staff member, I want to Manage Hearing Calendars, so that I can track hearing-related activities and due dates. | B30: Staff member | C30: Manage | D30: Hearing Calendars | K30: track | L30: hearing-related activities | M30: track | N30: due dates
A31: As a Staff member, I want to Assign a Hearing Date, so that I can present the application to the appropriate governing body within the timelines dictated by the relevant County rules and procedures. | B31: Staff member | C31: Assign | D31: Hearing Date | K31: present | L31: application
A32: As a Staff member, I want to Manage Affidavits, so that I can ensure compliance with the requirements prior to the hearing. | B32: Staff member | C32: Manage | D32: Affidavits | K32: ensure | L32: compliance
A33: As an Applicant, I want to Satisfy Hearing Requirements, so that I can ensure all pre-hearing requirements are satisfied in time for the hearing. | B33: Applicant | C33: Satisfy | D33: Hearing Requirements
A34: As a Staff member, I want to Prepare for and Support Hearing Execution, so that I can ensure all pre-hearing requirements are satisfied and staff and Applicant are ready for the hearing. | B34: Staff member | C34: Support | D34: Hearing Execution | E34: Prepare | F34: Hearing Execution
A35: As a Staff member, I want to Capture a Hearing Decision, so that I can enforce the system. | B35: Staff member | C35: Capture | D35: Hearing Decision | K35: enforce | L35: system
A36: As a Staff member, I want to Process the Appeals, so that I can track the outcome and record the impact on the relevant records. | B36: Staff member | C36: Process | D36: Appeals | K36: track | L36: outcome | M36: record | N36: impact
A37: As a Plan Review Staff member, I want to Assign Plans for Review, so that I can ensure plans have been assigned to the appropriate Plan Reviewer. | B37: Plan Review Staff member | C37: Assign | D37: Plans | K37: assigned | L37: plans
A38: As a Plan Review Staff Supervisor, I want to Manage Plan Reviewer Workload, so that I can monitor and effectively adjust workload as necessary and ensure service levels are met | B38: Plan Review Staff Supervisor | C38: Manage | D38: Plan Reviewer Workload | K38: monitor | L38: workload | M38: effectively adjust | N38: workload | O38: met | P38: service levels
A39: As an Applicant, I want to Request a Plan Review Meeting, so that I can meet with the Plan Review Staff regarding the plan review. | B39: Applicant | C39: Request | D39: Plan Review Meeting | K39: meet | L39: Plan Review Staff
A40: As a Plan Review Staff member, I want to successfully Conduct a Plan Review Meeting with the Applicant and record the outcome, so that I can listen to it again. | B40: Plan Review Staff member | C40: successfully Conduct | D40: Plan Review Meeting | E40: record | F40: outcome
...

Sheet Normalised
A1: ORIGINAL USID | B1: USID | C1: User Story Text | D1: Persona | E1: Activitiy | F1: Entity | G1: Part
A2: 1 | B2: G-1 | C2: As a Public User, I want to Search for Information. | D2: public user | E2: search | F2: information | G2: Goal
A3: 1 | B3: B-1 | C3: so that I can obtain publicly available information concerning properties, County services, processes and other general information. | D3: public user | E3: obtain | F3: publicly available information | G3: Benefit
A4: 2 | B4: G-2 | C4: As a ProspectiveApplicant, I want to research requirements and to select a service. | D4: prospectiveapplicant | E4: research | F4: requirement | G4: Goal
A5: 2 | B5: G-3 | C5: As a ProspectiveApplicant, I want to research requirements and to select a service. | D5: prospectiveapplicant | E5: select | F5: service | G5: Goal
A6: 2 | B6: B-2 | C6: so that I can find the relevant service and/or application type to initiate via the online portal. | D6: prospectiveapplicant | E6: find | F6: application type | G6: Benefit
A7: 2 | B7: B-3 | C7: so that I can find the relevant service and/or application type to initiate via the online portal. | D7: prospectiveapplicant | E7: find | F7: relevant service | G7: Benefit
A8: 2 | B8: B-4 | C8: so that I can find the relevant service and/or application type to initiate via the online portal. | D8: prospectiveapplicant | E8: initiate | F8: application type | G8: Benefit
A9: 2 | B9: B-5 | C9: so that I can find the relevant service and/or application type to initiate via the online portal. | D9: prospectiveapplicant | E9: initiate | F9: relevant service | G9: Benefit
A10: 3 | B10: G-4 | C10: As an Applicant, I want to Request PreApplication Assistance. | D10: applicant | E10: request | F10: preapplication assistance | G10: Goal
A11: 3 | B11: B-6 | C11: so that I can receive a response to a request for a meeting or information that is a result of the preapplication assistance. | D11: applicant | E11: receive | F11: response | G11: Benefit
A12: 3 | B12: B-7 | C12: so that I can receive a response to a request for a meeting or information that is a result of the preapplication assistance. | D12: applicant | E12: receive | F12: information | G12: Benefit
A13: 4 | B13: G-5 | C13: As a Customer, I want to Create a Customer Portal User Account. | D13: customer | E13: create | F13: customer portal user account | G13: Goal
... A172: 58 | B172: B-104 | C172: so that I can successfully send the Notice Of Violation document to the property owner and log information about the action. | D172: staff member | E172: log | F172: information | G172: Benefit

Sheet Normalised Goal
A1: ORIGINAL USID | B1: USID | C1: User Story Text | D1: Persona | E1: Activitiy | F1: Entity | G1: Part | H1: Modified
A2: 1 | B2: G-1 | C2: As a Public User, I want to Search for Information. | D2: public user | E2: search | F2: information | G2: Goal
A3: 2 | B3: G-2 | C3: As a ProspectiveApplicant, I want to research requirements. | D3: prospectiveapplicant | E3: research | F3: requirement | G3: Goal | H3: X
A4: 2 | B4: G-3 | C4: As a ProspectiveApplicant, I want to select a service. | D4: prospectiveapplicant | E4: select | F4: service | G4: Goal | H4: X
A5: 3 | B5: G-4 | C5: As an Applicant, I want to Request PreApplication Assistance. | D5: applicant | E5: request | F5: preapplication assistance | G5: Goal
A6: 4 | B6: G-5 | C6: As a Customer, I want to Create a Customer Portal User Account. | D6: customer | E6: create | F6: customer portal user account | G6: Goal
A7: 5 | B7: G-6 | C7: As an Applicant, I want to Submit Application. | D7: applicant | E7: submit | F7: application | G7: Goal
A8: 6 | B8: G-7 | C8: As an Applicant, I want to Submit Supporting Documentation. | D8: applicant | E8: submit | F8: support documentation | G8: Goal
A9: 7 | B9: G-8 | C9: As an Applicant, I want to Pay Fee. | D9: applicant | E9: pay | F9: fee | G9: Goal
A10: 8 | B10: G-9 | C10: As an Applicant, I want to Check the Status of a transaction. | D10: applicant | E10: check | F10: status | G10: Goal
A11: 9 | B11: G-10 | C11: As an Applicant, I want to Modify my Application. | D11: applicant | E11: modify | F11: application | G11: Goal
A12: 10 | B12: G-11 | C12: As a Staff member, I want to Perform a Completeness Review. | D12: staff member | E12: perform | F12: completeness review | G12: Goal
A13: 11 | B13: G-12 | C13: As a Staff member, I want to Record an Internal Note. | D13: staff member | E13: record | F13: internal note | G13: Goal
A14: 12 | B14: G-13 | C14: As a Staff member, I want to Assign an Application for Detailed Review. | D14: staff member | E14: assign | F14: application | G14: Goal
A15: 13 | B15: G-14 | C15: As a Staff member, I want to Apply a Hold. | D15: staff member | E15: apply | F15: hold | G15: Goal
A16: 14 | B16: G-15 | C16: As a Staff member, I want to Remove a Hold. | D16: staff member | E16: remove | F16: hold | G16: Goal
... A22: 20 | B22: G-21 | C22: As a staff member, I want to denote an application with a Final Action status.. | D22: staff member | E22: denote | F22: application | G22: Goal
A23: 21 | B23: G-22 | C23: As a Planning Staff member, I want to rack Plan Amendments. | D23: planning staff member | E23: track | F23: plan amendment | G23: Goal | H23: X
A24: 21 | B24: G-23 | C24: As a Planning Staff member, I want to Track Planning Studies. | D24: planning staff member | E24: track | F24: planning study | G24: Goal | H24: X
A25: 21 | B25: G-24 | C25: As a Planning Staff member, I want to Conduct Plan Amendments. | D25: planning staff member | E25: conduct | F25: plan amendment | G25: Goal | H25: X
A26: 21 | B26: G-25 | C26: As a Planning Staff member, I want to Conduct Planning Studies. | D26: planning staff member | E26: conduct | F26: planning study | G26: Goal | H26: X
A27: 22 | B27: G-26 | C27: As a Planning Staff member, I want to Generate Planning-related Reports. | D27: planning staff member | E27: generate | F27: planning - relate report | G27: Goal
A28: 23 | B28: G-27 | C28: As a Planning Staff member, I want to Evaluate Consistency with the Comprehensive Plan. | D28: planning staff member | E28: evaluate | F28: consistency | G28: Goal
A29: 24 | B29: G-28 | C29: As a Staff member, I want to Perform a Staff Review. | D29: staff member | E29: perform | F29: staff review | G29: Goal
A30: 25 | B30: G-29 | C30: As a Zoning Staff member, I want to Process the Requests for Zoning Information. | D30: zoning staff member | E30: process | F30: request | G30: Goal
A31: 26 | B31: G-30 | C31: As a Zoning Staff member, I want to Issue the Zoning-Related Permits. | D31: zoning staff member | E31: issue | F31: zoning - relate permit | G31: Goal
A32: 27 | B32: G-31 | C32: As a Staff member, I want to Develop a Staff Report. | D32: staff member | E32: develop | F32: staff report | G32: Goal
A33: 28 | B33: G-32 | C33: As a Staff member, I want to Manage Hearing Calendars. | D33: staff member | E33: manage | F33: hearing calendar | G33: Goal
A34: 29 | B34: G-33 | C34: As a Staff member, I want to Assign a Hearing Date. | D34: staff member | E34: assign | F34: hearing date | G34: Goal
A35: 30 | B35: G-34 | C35: As a Staff member, I want to Manage Affidavits. | D35: staff member | E35: manage | F35: affidavit | G35: Goal
A36: 31 | B36: G-35 | C36: As an Applicant, I want to Satisfy Hearing Requirements. | D36: applicant | E36: satisfy | F36: hearing requirement | G36: Goal
A37: 32 | B37: G-36 | C37: As a Staff member, I want to Support Hearing Execution. | D37: staff member | E37: support | F37: hearing execution | G37: Goal | H37: X
A38: 32 | B38: G-37 | C38: As a Staff member, I want to Prepare for Hearing Execution. | D38: staff member | E38: prepare | F38: hearing execution | G38: Goal | H38: X
A39: 33 | B39: G-38 | C39: As a Staff member, I want to Capture a Hearing Decision. | D39: staff member | E39: capture | F39: hearing decision | G39: Goal
A40: 34 | B40: G-39 | C40: As a Staff member, I want to Process the Appeals. | D40: staff member | E40: process | F40: appeal | G40: Goal
A41: 35 | B41: G-40 | C41: As a Plan Review Staff member, I want to Assign Plans for Review. | D41: plan review staff member | E41: assign | F41: plan | G41: Goal
A42: 36 | B42: G-41 | C42: As a Plan Review Staff Supervisor, I want to Manage Plan Reviewer Workload. | D42: plan review staff supervisor | E42: manage | F42: plan reviewer workload | G42: Goal
A43: 37 | B43: G-42 | C43: As an Applicant, I want to Request a Plan Review Meeting. | D43: applicant | E43: request | F43: plan review meeting | G43: Goal
A44: 38 | B44: G-43 | C44: As a Plan Review Staff member, I want to successfully Conduct a Plan Review Meeting with the Applicant. | D44: plan review staff member | E44: successfully conduct | F44: plan review meeting | G44: Goal | H44: X
A45: 38 | B45: G-44 | C45: As a Plan Review Staff member, I want to record the outcome. | D45: plan review staff member | E45: record | F45: outcome | G45: Goal | H45: X
...

Sheet CRUD-MAPPING
A1: ='Normalised Goal'!$A1 -> ORIGINAL USID | B1: ='Normalised Goal'!$B1 -> USID | C1: User Story | D1: Action | E1: Mapped | F1: Mapped | G1: Mapped | H1: Majority Decision | N1: context mit nehmen (mit für die Eval nehmen) | O1: wir könnten auch nur mal anschauen wie die Verbs gematched werden
A2: ='Normalised Goal'!$A2 -> 1 | B2: ='Normalised Goal'!$B2 -> G-1 | C2: ='Normalised Goal'!$C2 -> As a Public User, I want to Search for Information. | D2: ='Normalised Goal'!$E2 -> search | E2: r | F2: r | G2: r | H2: {=INDEX(_xlfn.UNIQUE($E2:$G2), MODE(MATCH(_xlfn.UNIQUE($E2:$G2), $E2:$G2, 0)))} -> r | K2: =_xlfn.XLOOKUP($D2, Normalised!H:H, Normalised!G:G, "") | L2: {=IFERROR(_xlfn.TEXTJOIN(",", TRUE, _xlfn._xlws.SORT(VALUE(_xlfn._xlws.FILTER(Normalised!G:G, Normalised!H:H=$D2)))), "")}
A3: ='Normalised Goal'!$A3 -> 2 | B3: ='Normalised Goal'!$B3 -> G-2 | C3: ='Normalised Goal'!$C3 -> As a ProspectiveApplicant, I want to research requirements. | D3: ='Normalised Goal'!$E3 -> research | E3: r | F3: r | G3: r | H3: {=INDEX(_xlfn.UNIQUE($E3:$G3), MODE(MATCH(_xlfn.UNIQUE($E3:$G3), $E3:$G3, 0)))} -> r | K3: =_xlfn.XLOOKUP($D3, Normalised!H:H, Normalised!G:G, "") | L3: {=IFERROR(_xlfn.TEXTJOIN(",", TRUE, _xlfn._xlws.SORT(VALUE(_xlfn._xlws.FILTER(Normalised!G:G, Normalised!H:H=$D3)))), "")}
A4: ='Normalised Goal'!$A4 -> 2 | B4: ='Normalised Goal'!$B4 -> G-3 | C4: ='Normalised Goal'!$C4 -> As a ProspectiveApplicant, I want to select a service. | D4: ='Normalised Goal'!$E4 -> select | E4: r | F4: r | G4: r | H4: {=INDEX(_xlfn.UNIQUE($E4:$G4), MODE(MATCH(_xlfn.UNIQUE($E4:$G4), $E4:$G4, 0)))} -> r | K4: =_xlfn.XLOOKUP($D4, Normalised!H:H, Normalised!G:G, "") | L4: {=IFERROR(_xlfn.TEXTJOIN(",", TRUE, _xlfn._xlws.SORT(VALUE(_xlfn._xlws.FILTER(Normalised!G:G, Normalised!H:H=$D4)))), "")}
A5: ='Normalised Goal'!$A5 -> 3 | B5: ='Normalised Goal'!$B5 -> G-4 | C5: ='Normalised Goal'!$C5 -> As an Applicant, I want to Request PreApplication Assistance. | D5: ='Normalised Goal'!$E5 -> request | E5: c | F5: c | G5: c | H5: {=INDEX(_xlfn.UNIQUE($E5:$G5), MODE(MATCH(_xlfn.UNIQUE($E5:$G5), $E5:$G5, 0)))} -> c
A6: ='Normalised Goal'!$A6 -> 4 | B6: ='Normalised Goal'!$B6 -> G-5 | C6: ='Normalised Goal'!$C6 -> As a Customer, I want to Create a Customer Portal User Account. | D6: ='Normalised Goal'!$E6 -> create | E6: c | F6: c | G6: c | H6: {=INDEX(_xlfn.UNIQUE($E6:$G6), MODE(MATCH(_xlfn.UNIQUE($E6:$G6), $E6:$G6, 0)))} -> c
A7: ='Normalised Goal'!$A7 -> 5 | B7: ='Normalised Goal'!$B7 -> G-6 | C7: ='Normalised Goal'!$C7 -> As an Applicant, I want to Submit Application. | D7: ='Normalised Goal'!$E7 -> submit | E7: c | F7: c | G7: c | H7: {=INDEX(_xlfn.UNIQUE($E7:$G7), MODE(MATCH(_xlfn.UNIQUE($E7:$G7), $E7:$G7, 0)))} -> c
A8: ='Normalised Goal'!$A8 -> 6 | B8: ='Normalised Goal'!$B8 -> G-7 | C8: ='Normalised Goal'!$C8 -> As an Applicant, I want to Submit Supporting Documentation. | D8: ='Normalised Goal'!$E8 -> submit | E8: c | F8: c | G8: c | H8: {=INDEX(_xlfn.UNIQUE($E8:$G8), MODE(MATCH(_xlfn.UNIQUE($E8:$G8), $E8:$G8, 0)))} -> c
A9: ='Normalised Goal'!$A9 -> 7 | B9: ='Normalised Goal'!$B9 -> G-8 | C9: ='Normalised Goal'!$C9 -> As an Applicant, I want to Pay Fee. | D9: ='Normalised Goal'!$E9 -> pay | E9: u | F9: r | G9: r | H9: {=INDEX(_xlfn.UNIQUE($E9:$G9), MODE(MATCH(_xlfn.UNIQUE($E9:$G9), $E9:$G9, 0)))} -> r
A10: ='Normalised Goal'!$A10 -> 8 | B10: ='Normalised Goal'!$B10 -> G-9 | C10: ='Normalised Goal'!$C10 -> As an Applicant, I want to Check the Status of a transaction. | D10: ='Normalised Goal'!$E10 -> check | E10: r | F10: r | G10: r | H10: {=INDEX(_xlfn.UNIQUE($E10:$G10), MODE(MATCH(_xlfn.UNIQUE($E10:$G10), $E10:$G10, 0)))} -> r
A11: ='Normalised Goal'!$A11 -> 9 | B11: ='Normalised Goal'!$B11 -> G-10 | C11: ='Normalised Goal'!$C11 -> As an Applicant, I want to Modify my Application. | D11: ='Normalised Goal'!$E11 -> modify | E11: u | F11: u | G11: u | H11: {=INDEX(_xlfn.UNIQUE($E11:$G11), MODE(MATCH(_xlfn.UNIQUE($E11:$G11), $E11:$G11, 0)))} -> u
A12: ='Normalised Goal'!$A12 -> 10 | B12: ='Normalised Goal'!$B12 -> G-11 | C12: ='Normalised Goal'!$C12 -> As a Staff member, I want to Perform a Completeness Review. | D12: ='Normalised Goal'!$E12 -> perform | E12: u | F12: c | G12: c | H12: {=INDEX(_xlfn.UNIQUE($E12:$G12), MODE(MATCH(_xlfn.UNIQUE($E12:$G12), $E12:$G12, 0)))} -> c
A13: ='Normalised Goal'!$A13 -> 11 | B13: ='Normalised Goal'!$B13 -> G-12 | C13: ='Normalised Goal'!$C13 -> As a Staff member, I want to Record an Internal Note. | D13: ='Normalised Goal'!$E13 -> record | E13: c | F13: c | G13: c | H13: {=INDEX(_xlfn.UNIQUE($E13:$G13), MODE(MATCH(_xlfn.UNIQUE($E13:$G13), $E13:$G13, 0)))} -> c
A14: ='Normalised Goal'!$A14 -> 12 | B14: ='Normalised Goal'!$B14 -> G-13 | C14: ='Normalised Goal'!$C14 -> As a Staff member, I want to Assign an Application for Detailed Review. | D14: ='Normalised Goal'!$E14 -> assign | E14: u | F14: c | G14: c | H14: {=INDEX(_xlfn.UNIQUE($E14:$G14), MODE(MATCH(_xlfn.UNIQUE($E14:$G14), $E14:$G14, 0)))} -> c
A15: ='Normalised Goal'!$A15 -> 13 | B15: ='Normalised Goal'!$B15 -> G-14 | C15: ='Normalised Goal'!$C15 -> As a Staff member, I want to Apply a Hold. | D15: ='Normalised Goal'!$E15 -> apply | E15: u | F15: c | G15: c | H15: {=INDEX(_xlfn.UNIQUE($E15:$G15), MODE(MATCH(_xlfn.UNIQUE($E15:$G15), $E15:$G15, 0)))} -> c
A16: ='Normalised Goal'!$A16 -> 14 | B16: ='Normalised Goal'!$B16 -> G-15 | C16: ='Normalised Goal'!$C16 -> As a Staff member, I want to Remove a Hold. | D16: ='Normalised Goal'!$E16 -> remove | E16: d | F16: d | G16: d | H16: {=INDEX(_xlfn.UNIQUE($E16:$G16), MODE(MATCH(_xlfn.UNIQUE($E16:$G16), $E16:$G16, 0)))} -> d
... A68: ='Normalised Goal'!$A68 -> 58 | B68: ='Normalised Goal'!$B68 -> G-67 | C68: ='Normalised Goal'!$C68 -> As a Staff member, I want to Send Fines. | D68: ='Normalised Goal'!$E68 -> send | E68: c | F68: c | G68: c | H68: {=INDEX(_xlfn.UNIQUE($E68:$G68), MODE(MATCH(_xlfn.UNIQUE($E68:$G68), $E68:$G68, 0)))} -> c
