Workbook

Sheet Info
A2: We have a modular approach for the data classification
A3: HS= Helpersheet
A4: P=Persona
A5: A=Activity
A6: E=Entity

Sheet Original Dataset
A1: / | C1: Goal - Action | K1: Benefit - Action
A2: Persona | B2: Goal Activity | C2: Goal Entity | D2: Goal Activity 2 | E2: Goal Entity 2 | F2: Goal Activity 3 | G2: Goal Entity 3 | H2: Benefit Activity | I2: Benefit Entity | J2: Benefit Activity 2 | K2: Benefit Entity 2 | L2: Benefit Activity 3 | M2: Benefit Entity 3 | N2: Benefit Activity 4 | O2: Benefit Entity 4
A3: PI | B3: properly record | C3: all metadata | H3: ensure | I3: proper running | J3: changes | K3: staff
A4: researcher | B4: indicate | C4: where | D4: indicate | E4: where | H4: stored | I4: data
A5: researcher | B5: import | C5: metadata
A6: data manager | B6: know | C6: how | H6: used | I6: data | J6: develop | K6: more detailed usage | L6: support | M6: scenarios
A7: repository owner | B7: check | C7: planned provenance | H7: calculate | I7: necessary submission fees
A8: IT manager | B8: know | C8: IT resource requirements | H8: enable | I8: resource acquisition planning
A9: PI | B9: plan | C9: kind of data I want to record/store
A10: IT staff member | B10: know | C10: security requirements | H10: know | I10: kind of security measures | J10: apply | K10: kind of security measures
A11: data manager | B11: have | C11: description | H11: add | I11: detail
A12: researcher | B12: know | C12: topics
A13: data manager | B13: know | C13: content | H13: decide | I13: collection | J13: decide | K13: repository
A14: PI | B14: record | C14: information
A15: legalofficer | B15: know | C15: data sensitivity | H15: establish | I15: sharing options
A16: data librarian | B16: extract | C16: pointers | H16: import | I16: metadata
A17: IT staff member | B17: have | C17: estimate | H17: plan | I17: overall storage consumption
A18: administrator | B18: know | C18: who | H18: funded | I18: project | J18: track | K18: funder specific obligations
A19: archivemanager | B19: know | C19: legal status | H19: apply | I19: legal requirements
A20: data manager | B20: know | C20: kind of data types | H20: determine | I20: basic support services | J20: determine | K20: functionalities
A21: IT staff member | B21: know | C21: kind of data types | H21: determine | I21: basic support services | J21: determine | K21: functionalities
A22: archivemanager | B22: know in advance | C22: conservation period | H22: better organize | I22: service | J22: adapting | K22: preservation actions
A23: data manager | B23: document | C23: all rights | H23: managing | I23: data | J23: curate | K23: data | L23: preserve | M23: data
A24: data manager | B24: know | C24: content | H24: maintaining | I24: intellectual reusability | J24: check | K24: necessary expertise
A25: research head | B25: access | C25: persistent identifiers | H25: check | I25: DMP | J25: implemented | K25: DMP
A26: funder | B26: read | C26: costs | H26: check | I26: policies
A27: researcher | B27: want | C27: DMP | H27: prepopulate | I27: information
A28: stakeholder | B28: know | C28: when | H28: created | I28: data management plan | J28: updated | K28: data management plan | L28: know | M28: how up-to-date | N28: updated | O28: data management plan
A29: stakeholder | B29: know | C29: who is responsible | H29: ask | I29: further details
A30: stakeholder | B30: have | C30: references | H30: look up | I30: further general information
A31: metadata manager | B31: have | C31: short description
A32: rector | B32: know | C32: how many | H32: stored | I32: data | J32: plan | K32: long term resources
A33: data manager | B33: know | C33: time plan | H33: collecting | I33: data | J33: plan | K33: data management
A34: data librarian | B34: import | C34: administrative information | H34: prepopulate | I34: DMP
A35: manager | B35: know | C35: all resources | D35: know | E35: services used | H35: estimate | I35: true cost
A36: archivemanager | B36: reuse | C36: information | H36: apply | I36: automated checks
A37: researcher | B37: know | C37: how many | H37: calculate | I37: costs
A38: researcher | B38: extract | C38: description | H38: writing | I38: data paper
A39: researcher | B39: record | C39: research publications | H39: generate | I39: reports
A40: researcher | B40: link | C40: research publications | H40: generate | I40: reports
...

Sheet Normalised
A1: ORIGINAL USID | B1: USID | C1: User Story Text | D1: Persona | E1: Activitiy | F1: Entity | G1: Part
A2: 1 | B2: G-1 | C2: As a PI, I want to properly record all metadata. | D2: pi | E2: properly record | F2: all metadata | G2: Goal
A3: 1 | B3: B-1 | C3: so that I can ensure proper running of the project in case of staff changes. | D3: pi | E3: ensure | F3: proper running | G3: Benefit
A4: 1 | B4: B-2 | C4: so that I can ensure proper running of the project in case of staff changes. | D4: pi | E4: change | F4: staff | G4: Benefit
A5: 2 | B5: G-2 | C5: As a researcher, I want to indicate where my data will be stored during the project and where after the project. | D5: researcher | E5: indicate | F5: where | G5: Goal
A6: 2 | B6: G-3 | C6: As a researcher, I want to indicate where my data will be stored during the project and where after the project. | D6: researcher | E6: indicate | F6: where | G6: Goal
A7: 2 | B7: B-3 | C7: so that it remains accessible during all stages of the data lifecycle. | D7: researcher | E7: store | F7: datum | G7: Benefit
A8: 3 | B8: G-4 | C8: As a researcher, I want to import metadata that I captured with a metadata tool. | D8: researcher | E8: import | F8: metadata | G8: Goal
A9: 4 | B9: G-5 | C9: As a data manager, I want to know how the data is used. | D9: data manager | E9: know | F9: how | G9: Goal
A10: 4 | B10: B-4 | C10: so that I can develop more detailed usage and support scenarios with researchers. | D10: data manager | E10: use | F10: datum | G10: Benefit
A11: 4 | B11: B-5 | C11: so that I can develop more detailed usage and support scenarios with researchers. | D11: data manager | E11: develop | F11: more detailed usage | G11: Benefit
A12: 4 | B12: B-6 | C12: so that I can develop more detailed usage and support scenarios with researchers. | D12: data manager | E12: support | F12: scenario | G12: Benefit
A13: 5 | B13: G-6 | C13: As a repository owner, I want to be able to check the planned provenance of the data that will be submitted at the end of a project. | D13: repository owner | E13: check | F13: plan provenance | G13: Goal
... A211: 83 | B211: B-126 | C211: so that I can proceed with the required next steps. | D211: data manager | E211: proceed | F211: required next step | G211: Benefit

Sheet Normalised Goal
A1: ORIGINAL USID | B1: USID | C1: User Story Text | D1: Persona | E1: Activitiy | F1: Entity | G1: Part
A2: 1 | B2: G-1 | C2: As a PI, I want to properly record all metadata. | D2: pi | E2: properly record | F2: all metadata | G2: Goal
A3: 2 | B3: G-2 | C3: As a researcher, I want to indicate where my data will be stored during the project | D3: researcher | E3: indicate | F3: where | G3: Goal
A4: 2 | B4: G-3 | C4: As a researcher, I want to indicate where my data will be stored after the project. | D4: researcher | E4: indicate | F4: my data | G4: Goal
A5: 3 | B5: G-4 | C5: As a researcher, I want to import metadata that I captured with a metadata tool. | D5: researcher | E5: import | F5: metadata | G5: Goal
A6: 4 | B6: G-5 | C6: As a data manager, I want to know how the data is used. | D6: data manager | E6: know | F6: how | G6: Goal
A7: 5 | B7: G-6 | C7: As a repository owner, I want to be able to check the planned provenance of the data that will be submitted at the end of a project. | D7: repository owner | E7: check | F7: plan provenance | G7: Goal
A8: 6 | B8: G-7 | C8: As an IT manager, I want to know about IT resource requirements early in the project lifecycle. | D8: it manager | E8: know | F8: it resource requirement | G8: Goal
A9: 7 | B9: G-8 | C9: As a PI, I want to plan what kind of data I want to record/store. | D9: pi | E9: plan | F9: kind of data I want to record / store | G9: Goal
A10: 8 | B10: G-9 | C10: As an IT staff member, I want to know the security requirements of the data. | D10: it staff member | E10: know | F10: security requirement | G10: Goal
A11: 9 | B11: G-10 | C11: As a data manager, I want to have the description of collected data sets that are used or updated throughout the project lifecycle. | D11: data manager | E11: have | F11: description | G11: Goal
A12: 10 | B12: G-11 | C12: As a researcher, I want to know which topics are mandatory and similar in all DMPs. | D12: researcher | E12: know | F12: topic | G12: Goal
A13: 11 | B13: G-12 | C13: As a data manager, I want to know what the content of the data is. | D13: data manager | E13: know | F13: content | G13: Goal
... A85: 82 | B85: G-84 | C85: As a repository manager, I want to have metadata in additional languages. | D85: repository manager | E85: have | F85: metadata | G85: Goal

Sheet CRUD-MAPPING
A1: ='Normalised Goal'!$A1 -> ORIGINAL USID | B1: ='Normalised Goal'!$B1 -> USID | C1: User Story | D1: Action | E1: Mapped | F1: Mapped | G1: Mapped | H1: Majority Decision | L1: context mit nehmen (mit für die Eval nehmen) | M1: wir könnten auch nur mal anschauen wie die Verbs gematched werden
A2: ='Normalised Goal'!$A2 -> 1 | B2: ='Normalised Goal'!$B2 -> G-1 | C2: ='Normalised Goal'!$C2 -> As a PI, I want to properly record all metadata. | D2: ='Normalised Goal'!$E2 -> properly record | E2: c | F2: c | G2: r | H2: {=INDEX(_xlfn.UNIQUE($E2:$G2), MODE(MATCH(_xlfn.UNIQUE($E2:$G2), $E2:$G2, 0)))} -> c | I2: =_xlfn.XLOOKUP($D2, Normalised!H:H, Normalised!G:G, "") | J2: {=IFERROR(_xlfn.TEXTJOIN(",", TRUE(), _xlfn._xlws.SORT(VALUE(_xlfn._xlws.FILTER(Normalised!G:G, Normalised!H:H=$D2)))), "")}
A3: ='Normalised Goal'!$A3 -> 2 | B3: ='Normalised Goal'!$B3 -> G-2 | C3: ='Normalised Goal'!$C3 -> As a researcher, I want to indicate where my data will be stored during the project | D3: ='Normalised Goal'!$E3 -> indicate | E3: c | F3: r | G3: c | H3: {=INDEX(_xlfn.UNIQUE($E3:$G3), MODE(MATCH(_xlfn.UNIQUE($E3:$G3), $E3:$G3, 0)))} -> c | I3: =_xlfn.XLOOKUP($D3, Normalised!H:H, Normalised!G:G, "") | J3: {=IFERROR(_xlfn.TEXTJOIN(",", TRUE(), _xlfn._xlws.SORT(VALUE(_xlfn._xlws.FILTER(Normalised!G:G, Normalised!H:H=$D3)))), "")}
A4: ='Normalised Goal'!$A4 -> 2 | B4: ='Normalised Goal'!$B4 -> G-3 | C4: ='Normalised Goal'!$C4 -> As a researcher, I want to indicate where my data will be stored after the project. | D4: ='Normalised Goal'!$E4 -> indicate | E4: c | F4: r | G4: c | H4: {=INDEX(_xlfn.UNIQUE($E4:$G4), MODE(MATCH(_xlfn.UNIQUE($E4:$G4), $E4:$G4, 0)))} -> c | I4: =_xlfn.XLOOKUP($D4, Normalised!H:H, Normalised!G:G, "") | J4: {=IFERROR(_xlfn.TEXTJOIN(",", TRUE(), _xlfn._xlws.SORT(VALUE(_xlfn._xlws.FILTER(Normalised!G:G, Normalised!H:H=$D4)))), "")}
A5: ='Normalised Goal'!$A5 -> 3 | B5: ='Normalised Goal'!$B5 -> G-4 | C5: ='Normalised Goal'!$C5 -> As a researcher, I want to import metadata that I captured with a metadata tool. | D5: ='Normalised Goal'!$E5 -> import | E5: r | F5: c | G5: r | H5: {=INDEX(_xlfn.UNIQUE($E5:$G5), MODE(MATCH(_xlfn.UNIQUE($E5:$G5), $E5:$G5, 0)))} -> r
A6: ='Normalised Goal'!$A6 -> 4 | B6: ='Normalised Goal'!$B6 -> G-5 | C6: ='Normalised Goal'!$C6 -> As a data manager, I want to know how the data is used. | D6: ='Normalised Goal'!$E6 -> know | E6: r | F6: r | G6: r | H6: {=INDEX(_xlfn.UNIQUE($E6:$G6), MODE(MATCH(_xlfn.UNIQUE($E6:$G6), $E6:$G6, 0)))} -> r
A7: ='Normalised Goal'!$A7 -> 5 | B7: ='Normalised Goal'!$B7 -> G-6 | C7: ='Normalised Goal'!$C7 -> As a repository owner, I want to be able to check the planned provenance of the data that will be submitted at the end of a project. | D7: ='Normalised Goal'!$E7 -> check | E7: r | F7: r | G7: r | H7: {=INDEX(_xlfn.UNIQUE($E7:$G7), MODE(MATCH(_xlfn.UNIQUE($E7:$G7), $E7:$G7, 0)))} -> r
A8: ='Normalised Goal'!$A8 -> 6 | B8: ='Normalised Goal'!$B8 -> G-7 | C8: ='Normalised Goal'!$C8 -> As an IT manager, I want to know about IT resource requirements early in the project lifecycle. | D8: ='Normalised Goal'!$E8 -> know | E8: r | F8: r | G8: r | H8: {=INDEX(_xlfn.UNIQUE($E8:$G8), MODE(MATCH(_xlfn.UNIQUE($E8:$G8), $E8:$G8, 0)))} -> r
A9: ='Normalised Goal'!$A9 -> 7 | B9: ='Normalised Goal'!$B9 -> G-8 | C9: ='Normalised Goal'!$C9 -> As a PI, I want to plan what kind of data I want to record/store. | D9: ='Normalised Goal'!$E9 -> plan | E9: u | F9: c | G9: u | H9: {=INDEX(_xlfn.UNIQUE($E9:$G9), MODE(MATCH(_xlfn.UNIQUE($E9:$G9), $E9:$G9, 0)))} -> u
A10: ='Normalised Goal'!$A10 -> 8 | B10: ='Normalised Goal'!$B10 -> G-9 | C10: ='Normalised Goal'!$C10 -> As an IT staff member, I want to know the security requirements of the data. | D10: ='Normalised Goal'!$E10 -> know | E10: r | F10: r | G10: r | H10: {=INDEX(_xlfn.UNIQUE($E10:$G10), MODE(MATCH(_xlfn.UNIQUE($E10:$G10), $E10:$G10, 0)))} -> r
A11: ='Normalised Goal'!$A11 -> 9 | B11: ='Normalised Goal'!$B11 -> G-10 | C11: ='Normalised Goal'!$C11 -> As a data manager, I want to have the description of collected data sets that are used or updated throughout the project lifecycle. | D11: ='Normalised Goal'!$E11 -> have | E11: r | F11: r | G11: r | H11: {=INDEX(_xlfn.UNIQUE($E11:$G11), MODE(MATCH(_xlfn.UNIQUE($E11:$G11), $E11:$G11, 0)))} -> r
A12: ='Normalised Goal'!$A12 -> 10 | B12: ='Normalised Goal'!$B12 -> G-11 | C12: ='Normalised Goal'!$C12 -> As a researcher, I want to know which topics are mandatory and similar in all DMPs. | D12: ='Normalised Goal'!$E12 -> know | E12: r | F12: r | G12: r | H12: {=INDEX(_xlfn.UNIQUE($E12:$G12), MODE(MATCH(_xlfn.UNIQUE($E12:$G12), $E12:$G12, 0)))} -> r
A13: ='Normalised Goal'!$A13 -> 11 | B13: ='Normalised Goal'!$B13 -> G-12 | C13: ='Normalised Goal'!$C13 -> As a data manager, I want to know what the content of the data is. | D13: ='Normalised Goal'!$E13 -> know | E13: r | F13: r | G13: r | H13: {=INDEX(_xlfn.UNIQUE($E13:$G13), MODE(MATCH(_xlfn.UNIQUE($E13:$G13), $E13:$G13, 0)))} -> r
A14: ='Normalised Goal'!$A14 -> 12 | B14: ='Normalised Goal'!$B14 -> G-13 | C14: ='Normalised Goal'!$C14 -> As a PI, I want to record information about my DMP. | D14: ='Normalised Goal'!$E14 -> record | E14: c | F14: c | G14: r | H14: {=INDEX(_xlfn.UNIQUE($E14:$G14), MODE(MATCH(_xlfn.UNIQUE($E14:$G14), $E14:$G14, 0)))} -> c
A15: ='Normalised Goal'!$A15 -> 13 | B15: ='Normalised Goal'!$B15 -> G-14 | C15: ='Normalised Goal'!$C15 -> As a legalofficer, I want to know about data sensitivity. | D15: ='Normalised Goal'!$E15 -> know | E15: r | F15: r | G15: r | H15: {=INDEX(_xlfn.UNIQUE($E15:$G15), MODE(MATCH(_xlfn.UNIQUE($E15:$G15), $E15:$G15, 0)))} -> r
A16: ='Normalised Goal'!$A16 -> 14 | B16: ='Normalised Goal'!$B16 -> G-15 | C16: ='Normalised Goal'!$C16 -> As a data librarian, I want to extract pointers from the DMP to metadata held in other systems. | D16: ='Normalised Goal'!$E16 -> extract | E16: c | F16: r | G16: r | H16: {=INDEX(_xlfn.UNIQUE($E16:$G16), MODE(MATCH(_xlfn.UNIQUE($E16:$G16), $E16:$G16, 0)))} -> r
... A85: ='Normalised Goal'!$A85 -> 82 | B85: ='Normalised Goal'!$B85 -> G-84 | C85: ='Normalised Goal'!$C85 -> As a repository manager, I want to have metadata in additional languages. | D85: ='Normalised Goal'!$E85 -> have | E85: c | F85: r | G85: r | H85: {=INDEX(_xlfn.UNIQUE($E85:$G85), MODE(MATCH(_xlfn.UNIQUE($E85:$G85), $E85:$G85, 0)))} -> r
